Traceback (most recent call last):
  File "C:\Users\Xinli\anaconda3\envs\ml22\lib\site-packages\jupyter_cache\executors\utils.py", line 51, in single_nb_execution
    executenb(
  File "C:\Users\Xinli\anaconda3\envs\ml22\lib\site-packages\nbclient\client.py", line 1204, in execute
    return NotebookClient(nb=nb, resources=resources, km=km, **kwargs).execute()
  File "C:\Users\Xinli\anaconda3\envs\ml22\lib\site-packages\nbclient\util.py", line 84, in wrapped
    return just_run(coro(*args, **kwargs))
  File "C:\Users\Xinli\anaconda3\envs\ml22\lib\site-packages\nbclient\util.py", line 62, in just_run
    return loop.run_until_complete(coro)
  File "C:\Users\Xinli\anaconda3\envs\ml22\lib\asyncio\base_events.py", line 647, in run_until_complete
    return future.result()
  File "C:\Users\Xinli\anaconda3\envs\ml22\lib\site-packages\nbclient\client.py", line 663, in async_execute
    await self.async_execute_cell(
  File "C:\Users\Xinli\anaconda3\envs\ml22\lib\site-packages\nbclient\client.py", line 965, in async_execute_cell
    await self._check_raise_for_error(cell, cell_index, exec_reply)
  File "C:\Users\Xinli\anaconda3\envs\ml22\lib\site-packages\nbclient\client.py", line 862, in _check_raise_for_error
    raise CellExecutionError.from_cell_and_msg(cell, exec_reply_content)
nbclient.exceptions.CellExecutionError: An error occurred while executing the following cell:
------------------
def getdf(df, y):
    df['Survived'] = y
    return df[['PassengerId', 'Survived']]

getdf(dftest, y_pred).to_csv('result.csv')
------------------

[1;31m---------------------------------------------------------------------------[0m
[1;31mNameError[0m                                 Traceback (most recent call last)
Input [1;32mIn [11][0m, in [0;36m<cell line: 5>[1;34m()[0m
[0;32m      2[0m     df[[38;5;124m'[39m[38;5;124mSurvived[39m[38;5;124m'[39m] [38;5;241m=[39m y
[0;32m      3[0m     [38;5;28;01mreturn[39;00m df[[[38;5;124m'[39m[38;5;124mPassengerId[39m[38;5;124m'[39m, [38;5;124m'[39m[38;5;124mSurvived[39m[38;5;124m'[39m]]
[1;32m----> 5[0m getdf(dftest, [43my_pred[49m)[38;5;241m.[39mto_csv([38;5;124m'[39m[38;5;124mresult.csv[39m[38;5;124m'[39m)

[1;31mNameError[0m: name 'y_pred' is not defined
NameError: name 'y_pred' is not defined

