Traceback (most recent call last):
  File "C:\Users\Xinli\anaconda3\envs\ml22\lib\site-packages\jupyter_cache\executors\utils.py", line 51, in single_nb_execution
    executenb(
  File "C:\Users\Xinli\anaconda3\envs\ml22\lib\site-packages\nbclient\client.py", line 1204, in execute
    return NotebookClient(nb=nb, resources=resources, km=km, **kwargs).execute()
  File "C:\Users\Xinli\anaconda3\envs\ml22\lib\site-packages\nbclient\util.py", line 84, in wrapped
    return just_run(coro(*args, **kwargs))
  File "C:\Users\Xinli\anaconda3\envs\ml22\lib\site-packages\nbclient\util.py", line 62, in just_run
    return loop.run_until_complete(coro)
  File "C:\Users\Xinli\anaconda3\envs\ml22\lib\asyncio\base_events.py", line 646, in run_until_complete
    return future.result()
  File "C:\Users\Xinli\anaconda3\envs\ml22\lib\site-packages\nbclient\client.py", line 663, in async_execute
    await self.async_execute_cell(
  File "C:\Users\Xinli\anaconda3\envs\ml22\lib\site-packages\nbclient\client.py", line 965, in async_execute_cell
    await self._check_raise_for_error(cell, cell_index, exec_reply)
  File "C:\Users\Xinli\anaconda3\envs\ml22\lib\site-packages\nbclient\client.py", line 862, in _check_raise_for_error
    raise CellExecutionError.from_cell_and_msg(cell, exec_reply_content)
nbclient.exceptions.CellExecutionError: An error occurred while executing the following cell:
------------------
import tensorflow as tf
# import keras
(x_train, y_train), (x_test, y_test) = tf.keras.datasets.mnist.load_data()
------------------

[1;31m---------------------------------[0m
[1;31mModuleNotFoundError[0mTraceback (most recent call last)
Input [1;32mIn [1][0m, in [0;36m<cell line: 1>[1;34m()[0m
[1;32m----> 1[0m [38;5;28;01mimport[39;00m [38;5;21;01mtensorflow[39;00m [38;5;28;01mas[39;00m [38;5;21;01mtf[39;00m
[0;32m      2[0m [38;5;66;03m# import keras[39;00m
[0;32m      3[0m (x_train, y_train), (x_test, y_test) [38;5;241m=[39m tf[38;5;241m.[39mkeras[38;5;241m.[39mdatasets[38;5;241m.[39mmnist[38;5;241m.[39mload_data()

[1;31mModuleNotFoundError[0m: No module named 'tensorflow'
ModuleNotFoundError: No module named 'tensorflow'

